<?xml version="1.0" encoding="UTF-8"?>
<!-- Generated by org.testng.reporters.JUnitReportReporter -->
<testsuite skipped="0" hostname="IB" name="TestAutomation.TechnicalTest.UserLogin_With_InValid" tests="2" failures="1" timestamp="15 Nov 2019 14:51:53 GMT" time="12.845" errors="0">
  <testcase name="UserLogin_With_Valid_UserID" time="2.796" classname="TestAutomation.TechnicalTest.UserLogin_With_InValid">
    <failure type="java.lang.AssertionError" message="expected [Login - My Store] but found [My account - My Store]">
      <![CDATA[java.lang.AssertionError: expected [Login - My Store] but found [My account - My Store]
	at org.testng.Assert.fail(Assert.java:94)
	at org.testng.Assert.failNotEquals(Assert.java:513)
	at org.testng.Assert.assertEqualsImpl(Assert.java:135)
	at org.testng.Assert.assertEquals(Assert.java:116)
	at org.testng.Assert.assertEquals(Assert.java:190)
	at org.testng.Assert.assertEquals(Assert.java:200)
	at TestAutomation.TechnicalTest.UserLogin_With_InValid.UserLogin_With_Valid_UserID(UserLogin_With_InValid.java:34)
	at sun.reflect.NativeMethodAccessorImpl.invoke0(Native Method)
	at sun.reflect.NativeMethodAccessorImpl.invoke(Unknown Source)
	at sun.reflect.DelegatingMethodAccessorImpl.invoke(Unknown Source)
	at java.lang.reflect.Method.invoke(Unknown Source)
	at org.testng.internal.MethodInvocationHelper.invokeMethod(MethodInvocationHelper.java:100)
	at org.testng.internal.Invoker.invokeMethod(Invoker.java:646)
	at org.testng.internal.Invoker.invokeTestMethod(Invoker.java:811)
	at org.testng.internal.Invoker.invokeTestMethods(Invoker.java:1137)
	at org.testng.internal.TestMethodWorker.invokeTestMethods(TestMethodWorker.java:129)
	at org.testng.internal.TestMethodWorker.run(TestMethodWorker.java:112)
	at org.testng.TestRunner.privateRun(TestRunner.java:753)
	at org.testng.TestRunner.run(TestRunner.java:607)
	at org.testng.SuiteRunner.runTest(SuiteRunner.java:368)
	at org.testng.SuiteRunner.runSequentially(SuiteRunner.java:363)
	at org.testng.SuiteRunner.privateRun(SuiteRunner.java:321)
	at org.testng.SuiteRunner.run(SuiteRunner.java:270)
	at org.testng.SuiteRunnerWorker.runSuite(SuiteRunnerWorker.java:52)
	at org.testng.SuiteRunnerWorker.run(SuiteRunnerWorker.java:86)
	at org.testng.TestNG.runSuitesSequentially(TestNG.java:1284)
	at org.testng.TestNG.runSuitesLocally(TestNG.java:1209)
	at org.testng.TestNG.runSuites(TestNG.java:1124)
	at org.testng.TestNG.run(TestNG.java:1096)
	at org.testng.remote.AbstractRemoteTestNG.run(AbstractRemoteTestNG.java:132)
	at org.testng.remote.RemoteTestNG.initAndRun(RemoteTestNG.java:236)
	at org.testng.remote.RemoteTestNG.main(RemoteTestNG.java:81)
]]>
    </failure>
  </testcase> <!-- UserLogin_With_Valid_UserID -->
  <testcase name="Lauch_Url_for_InValid_ID" time="10.049" classname="TestAutomation.TechnicalTest.UserLogin_With_InValid"/>
</testsuite> <!-- TestAutomation.TechnicalTest.UserLogin_With_InValid -->
